Workbook
Name Español: '3A 2025-2026 REPORTE CALIFICACI'!$C$8:$AL$50
Name distrito: 'DATOS DEL CENTRO'!$L$40:$L$59
Name zona: 'DATOS DEL CENTRO'!$I$40:$I$46
Name Física: '3A 2025-2026 REPORTE CALIFICACI'!$HA$8:$HR$50
Name familiaprofesional: #REF!
Name regional: 'DATOS DEL CENTRO'!$K$40:$K$58
Name Sociales: '3A 2025-2026 REPORTE CALIFICACI'!$EK$8:$FB$50
Name Formacion: '3A 2025-2026 REPORTE CALIFICACI'!$JQ$8:$KH$50
Name Inglés: '3A 2025-2026 REPORTE CALIFICACI'!$AM$8:$BD$50
Name anoescolar: 'DATOS DEL CENTRO'!$M$40:$M$60
Name aplazado: '3A 2025 - 2026 DATOS DEL ESTUDI'!$U$4:$U$43
Name Reingreso: '3A 2025 - 2026 DATOS DEL ESTUDI'!$T$4:$T$43
Name Francés: '3A 2025-2026 REPORTE CALIFICACI'!$BU$8:$CL$50
Name Matemática: '3A 2025-2026 REPORTE CALIFICACI'!$DC$8:$DT$50
Name Naturales: '3A 2025-2026 REPORTE CALIFICACI'!$FS$8:$GJ$50
Name sector: 'DATOS DEL CENTRO'!$H$40:$H$43
Name jornada: 'DATOS DEL CENTRO'!$J$40:$J$42
Name titulo: #REF!
Name Repitente: '3A 2025 - 2026 DATOS DEL ESTUDI'!$S$4:$S$43
Name promovido: '3A 2025 - 2026 DATOS DEL ESTUDI'!$R$4:$R$43
Name SECCION: 'DATOS DEL CENTRO'!$G$40:$G$44

Sheet DATOS DEL CENTRO
A11: REGISTRO ESCOLAR
A12: VERSIÓN DIGITAL PRELIMINAR INTERNA PARA VALIDACIÓN
A13: TERCERO GRADO
A14: NIVEL SECUNDARIO
A15: MODALIDAD ACADÉMICA
A17: DATOS DEL CENTRO
A18: CENTRO EDUCATIVO: | B18: PROFESOR JOSÉ MERCEDES ALVINO
A19: AÑO ESCOLAR: | B19: 2025-2026
A20: GRADO Y SECCIÓN: | B20: 3A
A21: DIRECCIÓN: | B21: AVENIDA HISPANOAMERICANA
A22: CORREO ELECTRÓNICO: | B22: CEJOMAL.2014@GMAIL.COM
A23: TELÉFONO: | B23: 8095706598
A24: CÓDIGO DE GESTIÓN SIGERD: | B24: 14601 | D24: CÓDIGO DE CARTOGRAFÍA:
A26: DATOS DEL DIRECTOR DEL CENTRO
A27: DIRECTOR DEL CENTRO: | B27: ZOILO MARRERO SIRÍ
A28: CORREO ELECTRÓNICO | D28: TELÉFONO: | E28: 809-399-8795
A30: DATOS DEL DOCENTE ENCARGADO DEL CURSO
A31: DOCENTE ENCARGADO DEL CURSO: | B31: MAYELIN GARCIA
A32: CORREO ELECTRÓNICO: | B32: mayelineducacion@gmail.com | D32: TELÉFONO: | E32: 829-682-1621
A34: SECTOR: | B34: PÚBLICO
A35: ZONA: | B35: URBANA
A36: JORNADA: | B36: JORNADA ESCOLAR EXTENDIDA
A37: REGIONAL: | B37: 8
A38: DISTRITO: | B38: 3
G39: GRADO Y SECCIÓN | H39: SECTOR | I39: ZONA | J39: JORNADA | K39: REGIONAL | L39: DISTRITO | M39: AÑO ESCOLAR
G40: 3A | H40: PÚBLICO | I40: URBANA | J40: JORNADA ESCOLAR EXTENDIDA | K40: 01 | L40: 01 | M40: 2019-2020
G41: 3B | H41: PRIVADO | I41: URBANA MARGINAL | J41: MATUTINA | K41: 02 | L41: 02 | M41: 2020-2021
G42: 3C | H42: SEMIOFICIAL | I42: URBANA TURÍSTICA | K42: 03 | L42: 03 | M42: 2021-2022
G43: 3D | I43: RURAL | K43: 04 | L43: 04 | M43: 2022-2023
I44: RURAL AISLADA | K44: 05 | L44: 05 | M44: 2023-2024
I45: RURAL TURÍSTICA | K45: 06 | L45: 06 | M45: 2024-2025
K46: 07 | L46: 07 | M46: 2025-2026
K47: 08 | L47: 08 | M47: 2026-2027
K48: 09 | L48: 09 | M48: 2027-2028
K49: 10 | L49: 10 | M49: 2028-2029
K50: 11 | L50: 11 | M50: 2029-2030
K51: 12 | L51: 12 | M51: 2030-2031
K52: 13 | L52: 13 | M52: 2031-2032
K53: 14 | L53: 14 | M53: 2032-2033
K54: 15 | L54: 15 | M54: 2033-2034
...

Sheet 3A 2025 - 2026 DATOS DEL ESTUDI
B1: DATOS DEL ESTUDIANTE | C1: Datos generales del estudiante | P1: TELÉFONO | Q1: CORREO ELECTRÓNICO | R1: Condición inicial del estudiante | V1: Evaluaciones de la asignaturas pendientes de !er. grado.
C2: Sexo | E2: Del acta de nacimiento | K2: NO. CÉDULA O PASAPORTE | M2: RNE | N2: ID | O2: Dirección donde reside
B3: NOMBRE (S) y APELLIDO (S) en orden alfabético | C3: Masculino | D3: Femenino | E3: Día | F3: Mes | G3: Año | H3: LIBRO | I3: FOLIO | J3: EDAD | R3: Promovido | S3: Repitente | T3: Reingreso | U3: Aplazado | V3: Calificaci'on asignatura reprobada | W3: Asignatura 1 | X3: Calificación oportunidad especial | Y3: Calificaci'on asignatura reprobada | Z3: Asignatura 2 | AA3: Calificación oportunidad especial
A4: 1 | B4: Jadiel De Jesús Acosta Peña | C4: X | E4: 5 | F4: 8 | G4: 2011 | H4: 00024 | I4: 0063 | J4: 14 | K4: 402-0318111-6 | N4: 32586041 | O4: Calle Arenoso Puñal | P4: 829-598-1159
A5: 2 | B5: Daniel Elía Almonte Martínez | C5: X | E5: 27 | F5: 7 | G5: 2011 | H5: 00005 | I5: 0156 | J5: 14 | K5: 402-0313940-3 | N5: 6954636 | O5: Calle # 28 Prados Del Yaque | P5: 829-689-8546
A6: 3 | B6: Isaac Ángeles Liriano | C6: X | E6: 2 | F6: 10 | G6: 2011 | H6: 00008-h | I6: 0168 | J6: 14 | K6: 402-4749369-1 | N6: 32743589 | O6: Calle Los Acosta Residencial Samantha | P6: 849-389-7275
A7: 4 | B7: Melaniee Aquino Estrella | D7: X | E7: 14 | F7: 9 | G7: 2011 | H7: 00009 | I7: 0138 | J7: 14 | K7: 402-0330053-4 | N7: 32899338 | O7: Calle Los Polfirio Canabacoa | P7: 849-402-5790
A8: 5 | B8: Jennifer Asenjo De Los Santos TRANSFERIDA 10/12/25 | D8: X | E8: 30 | F8: 9 | G8: 2011 | H8: 00007-A | I8: 0139 | J8: 14 | K8: 402-0480526-7 | N8: 33109621 | O8: Calle Principal Canabacoa | P8: 829-790-3720
A9: 6 | B9: Leshlie Crismayri Bautista Quezada | D9: X | E9: 5 | F9: 4 | G9: 2011 | H9: 00001 | I9: 0080 | J9: 14 | K9: 402-0274093-8 | N9: 32678295 | O9: Calle # 4 Villa Magisterial | P9: 829-750-5134
A10: 7 | B10: Gilber Bello Silva | C10: X | E10: 4 | F10: 4 | G10: 2011 | H10: 00010 | I10: 0139 | J10: 14 | K10: 402-0275073-9 | N10: 33224927 | O10: Calle Villa Rosa Canabacoa | P10: 829-522-2991
A11: 8 | B11: Sherlyn Mariel Bernabel Lora | D11: X | E11: 25 | F11: 10 | G11: 2010 | H11: 00029 | I11: 0155 | J11: 14 | K11: 402-0223867-7 | N11: 6783589 | O11: Calle Los Hiraldo Sabaneta | P11: 829-962*0422
A12: 9 | B12: Erleen Brito Castillo | C12: X | E12: 21 | F12: 12 | G12: 2011 | H12: 00002 | I12: 0091 | J12: 14 | K12: 402-0367930-9 | N12: 7117826 | O12: Calle Principal Canabacoa | P12: 809-517-6113
A13: 10 | B13: Brianny Caraballo Guzmán | D13: X | E13: 26 | F13: 12 | G13: 2011 | H13: 00037 | I13: 0183 | J13: 13 | K13: 402-0363743-0 | N13: 7042227 | O13: Calle Principal San Jose Puñal | P13: 849-650-4522
A14: 11 | B14: Scarlet Castillo | D14: X | E14: 5 | F14: 8 | G14: 2011 | H14: 00004-AD | I14: 0014 | J14: 14 | K14: 402-0346574-1 | N14: 32626669 | O14: Calle Arenoso Santiago | P14: 829-972-1642
A15: 12 | B15: Yarselin Cruz Peña | D15: X | E15: 6 | F15: 1 | G15: 2011 | H15: 00012-A | I15: 0151 | J15: 14 | K15: 402-0523505-0 | N15: 33016326 | O15: Calle #2 Casa 8 Canabacoa | P15: 809-961-9732
A16: 13 | B16: Fernando José Díaz Fernández | C16: X | E16: 21 | F16: 12 | G16: 2011 | H16: 00010-H | I16: 0107 | J16: 13 | K16: 402-5371389-1 | N16: 32387390 | O16: Dirección Colorado Calle 11 Apartamento 1B | P16: 829-931-4466
A17: 14 | B17: Scarlett Espinal Estéves | D17: X | E17: 18 | F17: 6 | G17: 2011 | H17: 00005-H | I17: 0004 | J17: 14 | K17: 402-3179174-6 | N17: 27198412 | O17: Calle Entrada Los Sanchéz Puñal | P17: 809-786-6381
A18: 15 | B18: José Manuel Estrella | C18: X | E18: 18 | F18: 3 | G18: 2011 | H18: 00013-A | I18: 0123 | J18: 14 | K18: 402-0533893-8 | N18: 33382609 | O18: Calle Los Polfirio Canabacoa | P18: 809-666-8642
A19: 16 | B19: Misael Starberk Ferreras Pérez | C19: X | E19: 31 | F19: 1 | G19: 2012 | H19: 00002-UMT | I19: 0091 | J19: 13 | K19: 402-3432676-3 | N19: 32745811 | O19: Calle # 3 Arenoso | P19: 829-361-7881
A20: 17 | B20: Ruth Esther Fernández Rodríguez | D20: X | E20: 8 | F20: 1 | G20: 2009 | H20: 00002 | I20: 0039 | J20: 16 | K20: 402-0610467-0 | N20: 6739413 | O20: Calle Hispanoamericana Canabacoa | P20: 849-354-9216
A21: 18 | B21: Discairy Filpo Estrella | D21: X | E21: 22 | F21: 8 | G21: 2011 | H21: 00005 | I21: 0157 | J21: 14 | K21: 402-0314077-3 | N21: 32812732 | O21: Calle Los Filpo | P21: 809-758-0030
A22: 19 | B22: Alexis Enmanuel Gil Sánchez | C22: X | E22: 31 | F22: 12 | G22: 2011 | H22: 00001 | I22: 0018 | J22: 13 | K22: 402-0365191-0 | N22: 32529336 | O22: Calle Maximo Gómez, Barrio Obrero | P22: 829-548-5404
A23: 20 | B23: Ayendy Jesús Guzmán | C23: X | E23: 19 | F23: 6 | G23: 2010 | H23: 0000-UMT | I23: 0084 | J23: 15 | K23: 402-1598153-7 | N23: 22047916 | O23: Calle Reparto # 4 Arenoso | P23: 809-486-1394
A24: 21 | B24: Yassir Hernández Disla | C24: X | E24: 13 | F24: 9 | G24: 2011 | H24: 00030 | I24: 0039 | J24: 14 | K24: 402-0336591-7 | N24: 32387479 | O24: Calle Principal Arenoso Los Cabrales | P24: 829-630-5000
A25: 22 | B25: Yadiel Jiménez Betances | C25: X | E25: 14 | F25: 11 | G25: 2009 | H25: 00004-UMT | I25: 0083 | J25: 15 | K25: 402-3737081-8 | N25: 6635033 | O25: Calle Los Castillo . | P25: 829-620-1823
A26: 23 | B26: Yamel Mella Aquino | D26: X | E26: 18 | F26: 8 | G26: 2011 | H26: 00005-UMT | I26: 0149 | J26: 14 | K26: 402-3859228-7 | N26: 32857385 | O26: Canabacoa | P26: 849-376-8904
A27: 24 | B27: Sariely Del Carmen Mena Chávez | D27: X | E27: 25 | F27: 11 | G27: 2008 | H27: 00029 | I27: 0049 | J27: 16 | K27: 402-0609607-3 | N27: 6396255 | O27: Calle Principal De Canabacoa | P27: 809-996-1179
A28: 25 | B28: David Carmelo Navas Fernández | C28: X | E28: 1 | F28: 5 | G28: 2011 | N28: 33560794 | O28: Calle Enriquillo # 7 Villa Centro | P28: 829-425-9171
A29: 26 | B29: Andriw Jelier Ortiz Rodríguez | C29: X | E29: 7 | F29: 6 | G29: 2011 | H29: 00007 | I29: 0165 | J29: 14 | K29: 402-0298775-2 | N29: 32720987 | O29: Calle Vivero Villa Centro | P29: 829-894-0025
A30: 27 | B30: Dashley Nicole Peña García | D30: X | E30: 29 | F30: 6 | G30: 2011 | H30: 00018 | I30: 0081 | J30: 14 | K30: 402-0298790-1 | N30: 32899290 | O30: Calle Los Castillo | P30: 809-492-0579
A31: 28 | B31: Yesly Peña Muñoz | D31: X | E31: 26 | F31: 6 | G31: 2011 | H31: 00004 | I31: 0123 | J31: 14 | K31: 402-0298535-0 | N31: 32607334 | O31: Calle Libertad # 12 Barrio Lindo | P31: 809-672-1316
A32: 29 | B32: Wilbert Peña Paulino | C32: X | E32: 1 | F32: 8 | G32: 2011 | H32: 00022 | I32: 0126 | J32: 14 | K32: 402-0311880-3 | N32: 32687351 | O32: Calle Penetracion # 2 Los Castillo | P32: 849-471-4573
A33: 30 | B33: Yonayry Peña Santos | D33: X | E33: 25 | F33: 5 | G33: 2011 | H33: 00001 | I33: 0013 | J33: 14 | K33: 402-0288777-0 | N33: 6445759 | O33: Calle Los Porfirio Canabacoa | P33: 809-452-4811
A34: 31 | B34: Rossier Analiz Pérez Rodríguez | D34: X | E34: 10 | F34: 10 | G34: 2011 | H34: 00006 | I34: 0197 | J34: 14 | K34: 402-0333034-1 | N34: 22023376 | O34: Calle Av Hispanoamericana, Canabacoa | P34: 809-905-5978
A35: 32 | B35: Joseph Francisco Ramírez Espinosa | C35: X | E35: 4 | F35: 10 | G35: 2011 | H35: 00006 | I35: 0055 | J35: 14 | K35: 402-3282770-5 | N35: 6925657 | O35: Dirección, Rafael Vidal Santiago | P35: 849-382-8985
A36: 33 | B36: Yariel Alfonso Ramos | C36: X | E36: 26 | F36: 11 | G36: 2009 | H36: 00001 | I36: 0141 | J36: 15 | K36: 402-0131926-5 | N36: 12009792 | O36: Calle 10 Canabacoa | P36: 829-922-1122
A37: 34 | B37: Carlos David Rodríguez Almánzar | C37: X | E37: 29 | F37: 1 | G37: 2012 | H37: 00008 | I37: 0101 | J37: 13 | K37: 402-0390302-2 | N37: 32790184 | O37: Calle Villa Rosa Canabacoa | P37: 849-497-8171
A38: 35 | B38: Darianni Santos Medina | D38: X | E38: 26 | F38: 1 | G38: 2012 | H38: 00001-H | I38: 0139 | J38: 13 | K38: 402-1847857-2 | N38: 32790393 | O38: Calle Autopista Duarte Canabacoa | P38: 809-729-3458
A39: 36 | B39: Rosyeli Carolina Tavarez Reyes | D39: X | E39: 19 | F39: 3 | G39: 2011 | H39: 00004 | I39: 0061 | J39: 14 | K39: 402-0277696-5 | N39: 6947490 | O39: Calle 26 # 18 Pekin | P39: 829-523-6211
A40: 37 | B40: Melani Taveras Bautista | D40: X | E40: 15 | F40: 2 | G40: 2011 | H40: 00007 | I40: 0062 | J40: 14 | K40: 402-0264895-8 | N40: 32590071 | O40: Calle 2 Canabacoa | P40: 829-653-0117
...

Sheet 3A 2025 - 2026 D. E
A1: DATOS PARA EMERGENCIAS
B2: De salud | D2: Llamar a: | F2: Parentesco persona con la que vive
B3: Enfermedades o alérgico | C3: Medicamentos que usa | D3: Nombre y Apellido | E3: Teléfono
A4: 1 | D4: Erica María Peña Estrella | E4: 829-598-1159 | F4: Madre
A5: 2 | D5: Dionicio Almonte | E5: 829-689-8546 | F5: Padre
A6: 3 | D6: Jusmil Liriano Sanchez | E6: 849-389-7275 | F6: Madre
A7: 4 | B7: Problemas Visuales | D7: Suhedy Estrella | E7: 849-402-5790 | F7: Tia
A8: 5 | B8: Problemas Auditivos | D8: Estefany De Los Santos | E8: 829-790-3720
A9: 6 | D9: Luis Ramon Bautista LLuberes | E9: 829-750-5134 | F9: Padre
A10: 7 | B10: Gastritis, Anemia, Alergias | D10: Claudia Silva Jimenez | E10: 829-522-2991 | F10: Madre
A11: 8 | D11: Manuel Antonio Bernabel | E11: 829-962*0422 | F11: Tio
A12: 9 | D12: Manuel Ramon Brito Albino | E12: 809-517-6113 | F12: Padre
A13: 10 | B13: Sinusitis, Alergias | D13: Milcia Griseline Guzmán Guzmán | E13: 849-650-4522 | F13: Madre
A14: 11 | B14: Gastritis, Alergias | D14: Eduanny Castillo Lantigua | E14: 829-972-1642 | F14: Madre
A15: 12 | D15: Fatima Altagracia Nuñez | E15: 809-961-9732 | F15: Madre o De Crianza
A16: 13 | B16: Asma, Sinusitis, Alergias | D16: Genesis Fernández Camacho | E16: 829-931-4466 | F16: Madre
A17: 14 | B17: Alergias | D17: Kary Altagracia Esteves Franco | E17: 809-786-6381 | F17: Madre
A18: 15 | D18: Benjamin Estrella | E18: 809-666-8642 | F18: Abuelo
A19: 16 | D19: Vetalin Ferreras Jimenez | E19: 829-361-7881
A20: 17 | D20: Jose Manuel Fernández Rodríguez | E20: 849-354-9216 | F20: Padre
A21: 18 | D21: Carmen Rosa Estrella Rojas | E21: 809-758-0030 | F21: Madre
A22: 19 | B22: Problemas Visuales | D22: Yanilda Sánchez Santana | E22: 829-548-5404 | F22: Madre
A23: 20 | D23: Hector Gúzman | E23: 809-486-1394 | F23: Abuelo
A24: 21 | B24: Problemas Visuales | D24: María Mercedes Disla Paulino | E24: 829-630-5000 | F24: Madre
A25: 22 | D25: Yanely Betances | E25: 829-620-1823 | F25: Tia
A26: 23 | D26: Ysrael Mella Feliz | E26: 849-376-8904 | F26: Padre
A27: 24 | D27: María Paula Chavez Santos | E27: 809-996-1179 | F27: Madre
A28: 25 | B28: Problemas Visuales | D28: Angelica María Fernández Madrid | E28: 829-425-9171 | F28: Madre
A29: 26 | B29: Alergias | D29: Glennys Rodríguez Ovalle | E29: 829-894-0025 | F29: Madre
A30: 27 | B30: Alergias | D30: Romayrin Annerys Garcia Lantigua | E30: 809-492-0579 | F30: Madre
A31: 28 | D31: Yensi Muñoz Taveras | E31: 809-672-1316 | F31: Madre
A32: 29 | D32: Willian Javier Peña Peña | E32: 849-471-4573 | F32: Padre
A33: 30 | B33: Migraña, Alergias, Problemas Visuales | D33: Yomary Altagracia Santos | E33: 809-452-4811 | F33: Madre
A34: 31 | D34: Juana Yomaira Rodríguez Tavarez | E34: 809-905-5978 | F34: Madre
A35: 32 | D35: Iliana Del Carmen Espinosa Garcia | E35: 849-382-8985 | F35: Madre
A36: 33 | B36: Alergias | D36: Dominga Altagracia | E36: 829-922-1122
A37: 34 | B37: Problemas Visuales | D37: Jahaira Alvino Gil | E37: 849-497-8171 | F37: Tia
A38: 35 | D38: Dahyana Santos Medina | E38: 809-729-3458 | F38: Hemana
A39: 36 | B39: Alergias | D39: Jennipher Carolina Reyes Sánchez | E39: 829-523-6211 | F39: Madre
A40: 37 | D40: Flor D' Aliza Bautista Estevez | E40: 829-653-0117 | F40: Madre
...

Sheet 3A 2025-2026 P. E
A1: PARENTESCO
B2: PADRE | D2: MADRE | F2: TUTOR
B3: Nombre (s) y Apellido (s) | C3: Teléfono | D3: Nombre (s) y Apellido (s) | E3: Teléfono | F3: Nombre (s) y Apellido (s) | G3: Teléfono
A4: 1 | B4: Jose Ambiorix Acosta De León | D4: Erica María Peña Estrella | E4: 829-598-1159 | F4: Erica María Peña Estrella | G4: 829-598-1159
A5: 2 | B5: Dionicio Antonio Almonte Almonte | C5: 829-689-8546 | D5: Ludilce Virginia Martínez Espinal | E5: 849-283-2417 | F5: Dionicio Almonte | G5: 829-689-8546
A6: 3 | B6: Victoriano Angeles Cruz | C6: 829-671-8784 | D6: Jusmil Liriano Sanchez | E6: 849-389-7275 | F6: Jusmil Liriano Sanchez | G6: 849-389-7275
A7: 4 | B7: Carlos Aquino Garcia | D7: Dayarlin Estrella Estrella | E7: 849-402-5790 | F7: Suhedy Estrella | G7: 809-609-0846
A8: 5 | B8: Jefferson Asenjo Polanco | D8: Estefany De Los Santos | E8: 829-790-3720 | F8: Estefany De Los Santos | G8: 829-790-3720
A9: 6 | B9: Luis Ramon Bautista LLuberes | C9: 829-750-5134 | D9: Crisbelys Gesabel Quezada | E9: 809-543-6993 | F9: Luis Ramon Bautista LLuberes | G9: 829-750-5134
A10: 7 | B10: Hector Radhames Bello Batista | D10: Claudia Silva Jimenez | E10: 829-522-2991 | F10: Claudia Silva Jimenez | G10: 829-522-2991
A11: 8 | B11: Kelvyn Antonio Bernabel Germoso | C11: 809-848-3818 | D11: Mariela Lora Vásquez | E11: 829-672-7664 | F11: Manuel Antonio Bernabel | G11: 829-962-0422
A12: 9 | B12: Manuel Ramon Brito Albino | C12: 809-517-6113 | D12: Ana Evelin Castillo Tavarez | E12: 849-203-3469 | F12: Manuel Ramon Brito Albino | G12: 809-517-6113
A13: 10 | B13: Jose Leonardo Caraballo Sánchez | C13: 829-958-2857 | D13: Milcia Griseline Guzmán Guzmán | E13: 849-650-4522 | F13: Milcia Griseline Guzmán Guzmán | G13: 849-650-4522
A14: 11 | D14: Eduanny Castillo Lantigua | E14: 829-972-1642 | F14: Eduanny Castillo Lantigua | G14: 829-972-1642
A15: 12 | B15: Nelson Antonio Cruz Jaquez | C15: 809-713-6993 | D15: Yinet Del Carmen Peña Muñoz | E15: 829-821-7597 | F15: Fatima Altagracia Nuñez | G15: 809-961-9732
A16: 13 | B16: José Ramon Diaz Dominguez | C16: 849-623-7105 | D16: Genesis Fernández Camacho | E16: 829-931-4466 | F16: Genesis Fernández Camacho | G16: 829-931-4466
A17: 14 | B17: Willy Espinal Santos | C17: 829-335-7556 | D17: Kary Altagracia Esteves Franco | E17: 809-786-6381 | F17: Kary Altagracia Esteves Franco | G17: 809-786-6381
A18: 15 | D18: Yahaira María Estrella | E18: 809-386-7578 | F18: Yahaira María Estrella | G18: 809-666-8642
A19: 16 | B19: Vetalin Ferreras Jimenez | C19: 829-361-7881 | D19: Belkis Pérez | E19: 809-767-8092 | F19: Belkis Pérez | G19: 829-361-7881
A20: 17 | B20: Jose Manuel Fernández Rodríguez | C20: 849-354-9216 | D20: Hilda Rodríguez | F20: Jose Manuel Fernández Rodríguez | G20: 849-354-9216
A21: 18 | B21: Wilson De Jesús Filpo Gutierrez | C21: 829-353-7052 | D21: Carmen Rosa Estrella Rojas | E21: 809-758-0030 | F21: Carmen Rosa Estrella Rojas | G21: 809-758-0030
A22: 19 | B22: Emmanuel Espugny Alexander Gil Guzmán | C22: 829-981-3015 | D22: Yanilda Sánchez Santana | E22: 829-548-5404 | F22: Yanilda Sánchez Santana | G22: 829-548-5404
A23: 20 | D23: Yaleiry Guzmán | E23: 829-540-3003 | F23: Yaleiry Guzmán | G23: 809-486-1394
A24: 21 | B24: Justo Hernandez Sánchez | C24: 954-471-0496 | D24: María Mercedes Disla Paulino | E24: 829-630-5000 | F24: María Mercedes Disla Paulino | G24: 809-570-7493
A25: 22 | B25: Juan Gabriel Jimenez Garcia | C25: 849-656-2662 | D25: Esthefanie Altagracia Betances Cruz | E25: 829-210-3799 | F25: Yanely Betances | G25: 829-620-1823
A26: 23 | B26: Ysrael Mella Feliz | C26: 849-376-8904 | D26: Magaly Altagracia Aquino Galan | E26: 849-376-8904 | F26: Ysrael Mella Feliz | G26: 849-376-8904
A27: 24 | B27: Santos Rufino Mena Martínez | C27: 849-847-2028 | D27: María Paula Chavez Santos | E27: 809-996-1179 | F27: María Paula Chavez Santos | G27: 809-996-1179
A28: 25 | B28: Italo Carmelo Navas Ibarra | C28: 829-294-1623 | D28: Angelica María Fernández Madrid | E28: 829-425-9171 | F28: Angelica María Fernández Madrid | G28: 829-425-9171
A29: 26 | B29: Pedro Antonio Ortiz | C29: 849-443-7091 | D29: Glennys Rodríguez Ovalle | E29: 829-894-0025 | F29: Glennys Rodríguez Ovalle | G29: 829-8940025
A30: 27 | B30: Jose Luis Peña Baez | C30: 829-462-2136 | D30: Romayrin Annerys Garcia Lantigua | E30: 809-492-0579 | F30: Romayrin Annerys Garcia Lantigua | G30: 809-492-0579
A31: 28 | B31: Robinson Raul Peña | C31: 829-663-2746 | D31: Yensi Muñoz Taveras | E31: 809-672-1316 | F31: Yensi Muñoz Taveras | G31: 809-672-1316
A32: 29 | B32: Willian Javier Peña Peña | C32: 849-477-4573 | D32: Sandra Altagracia Paulino Garcia | E32: 809-330-2795 | F32: Willian Javier Peña Peña | G32: 809-330-2795
A33: 30 | B33: Gilberto Antonio Peña Santana | C33: 829-347-7893 | D33: Yomary Altagracia Santos | E33: 809-452-4811 | F33: Yomary Altagracia Santos | G33: 809-452-4811
A34: 31 | B34: Juan Carlos Perez Gúzman | C34: 809-575-3685 | D34: Juana Yomaira Rodríguez Tavarez | E34: 809-905-5978 | F34: Juana Yomaira Rodríguez Tavarez | G34: 809-905-5978
A35: 32 | B35: Jose Luis Ramirez Garcia | C35: 809-271-8747 | D35: Iliana Del Carmen Espinosa Garcia | E35: 849-382-8985 | F35: Iliana Del Carmen Espinosa Garcia | G35: 849-382-8985
A36: 33 | D36: Saoni Alfonsina Ramos Rodríguez | E36: 809-612-3130 | F36: Dominga Altagracia | G36: 829-922-1122
A37: 34 | B37: Calos De Jesús Rodríguez Gil | C37: 809-494-5263 | D37: Yumeiry Altagracia Almanzar | E37: 829-919-0088 | F37: Jahaira Alvino Gil | G37: 849-497-8171
A38: 35 | B38: Confesor Santos Amaro | C38: 809-871-7148 | D38: Aida Medina Santos | E38: 829-259-1827 | F38: Aida Medina Santos | G38: 809-729-3458
A39: 36 | B39: Robinson Enmanuel Tavarez Peguero | C39: 829-694-2841 | D39: Jennipher Carolina Reyes Sánchez | E39: 829-523-6211 | F39: Jennipher Carolina Reyes Sánchez | G39: 829-523-6211
A40: 37 | B40: Pablo Taveras Martínez | C40: 829-366-8399 | D40: Flor D' Aliza Bautista Estevez | E40: 829-653-0117 | F40: Flor D' Aliza Bautista Estevez | G40: 829-653-0117
...

Sheet ALE316
D1: LENGUA ESPAÑOLA
D2: DOCENTE: | H2: ='DATOS DOCENTES'!B2 -> MAYELIN GARCÍA
D3: Mes: | F3: AGOSTO | AG3: Mes: | AI3: SEPTIEMBRE
D4: DÍAS TRABAJADOS | Z4: 5 | AG4: DÍAS TRABAJADOS | BC4: 17
D5: 1 | E5: 2 | F5: 3 | G5: 4 | H5: 5 | I5: 6 | J5: 7 | K5: 8 | L5: 9 | M5: 10 | N5: 11 | O5: 12 | P5: 13 | Q5: 14 | R5: 15 | S5: 16 | T5: 17 | U5: 18 | V5: 19 | W5: 20 | X5: 21 | Y5: TP | Z5: % P | AA5: TA | AB5: %A | AC5: TE | AD5: %E | AG5: 1 | AH5: 2 | AI5: 3 | AJ5: 4 | AK5: 5 | AL5: 6 | AM5: 7 | AN5: 8 | AO5: 9 | AP5: 10 | AQ5: 11 | AR5: 12 | AS5: 13 | AT5: 14 | AU5: 15 | AV5: 16 | AW5: 17 | AX5: 18 | AY5: 19 | AZ5: 20 | BA5: 21 | BB5: TP | BC5: % P | BD5: TA | BE5: %A | BF5: TE | BG5: %E
A6: ID | B6: Días | C6: NOMBRE (S) Y APELLIDO (S) | D6: 25 | E6: 26 | F6: 27 | G6: 28 | H6: 29 | AE6: No. | AF6: NOMBRE (S) Y APELLIDO (S) | AG6: 1 | AH6: 2 | AI6: 3 | AJ6: 4 | AK6: 5 | AL6: 8 | AM6: 9 | AN6: 10 | AO6: 11 | AP6: 12 | AQ6: 15 | AR6: 16 | AS6: 17 | AT6: 18 | AU6: 19 | AV6: 22 | AW6: 23 | AX6: 24 | AY6: 25 | AZ6: 26 | BA6: 29 | BN6: ASIGNATURA | BO6: MES | BP6: DÍAS
A7: ='3A 2025 - 2026 DATOS DEL ESTUDI'!N4 -> 32586041 | B7: 1 | C7: ='3A 2025 - 2026 DATOS DEL ESTUDI'!B4 -> Jadiel De Jesús Acosta Peña | D7: P | E7: P | F7: P | G7: P | H7: P | Y7: =IFERROR(COUNTIF(D7:X7,"P")+COUNTIF(D7:X7,"e")+COUNTIF(D7:X7,"t")-INT(COUNTIF(D7:X7,"e")/3)-INT(COUNTIF(D7:X7,"t")/3),"") -> 5 | Z7: =IFERROR((Y7/$Z$4),"") -> 1 | AA7: =IFERROR(COUNTIF(D7:X7,"A"),"") -> 0 | AB7: =IFERROR((AA7/$Z$4),"") -> 0 | AC7: =IFERROR(COUNTIF(D7:X7,"E"),"") -> 0 | AD7: =IFERROR((AC7/$Z$4),"") -> 0 | AE7: 1 | AF7: =C7 -> Jadiel De Jesús Acosta Peña | AG7: P | AH7: P | AI7: P | AJ7: P | AK7: P | AL7: P | AM7: P | AN7: P | AO7: P | AP7: P | AQ7: P | AR7: P | AU7: P | AV7: P | AW7: P | AY7: P | BA7: P | BB7: =IFERROR(COUNTIF(AG7:BA7,"P")+COUNTIF(AG7:BA7,"e")+COUNTIF(AG7:BA7,"t")-INT(COUNTIF(AG7:BA7,"e")/3)-INT(COUNTIF(AG7:BA7,"t")/3),"") -> 17 | BC7: =IFERROR(BB7/$BC$4,"") -> 1 | BD7: =IFERROR(COUNTIF(AG7:BA7,"A"),"") -> 0 | BE7: =IFERROR((BD7/$BC$4),"") -> 0 | BF7: =IFERROR(COUNTIF(AG7:BA7,"E"),"") -> 0 | BG7: =IFERROR((BF7/$BC$4),"") -> 0 | BN7: LENGUA ESPAÑOLA | BO7: ENERO | BP7: 1
A8: ='3A 2025 - 2026 DATOS DEL ESTUDI'!N5 -> 6954636 | B8: 2 | C8: ='3A 2025 - 2026 DATOS DEL ESTUDI'!B5 -> Daniel Elía Almonte Martínez | D8: P | E8: P | F8: P | G8: P | H8: P | Y8: =IFERROR(COUNTIF(D8:X8,"P")+COUNTIF(D8:X8,"e")+COUNTIF(D8:X8,"t")-INT(COUNTIF(D8:X8,"e")/3)-INT(COUNTIF(D8:X8,"t")/3),"") -> 5 | Z8: =IFERROR((Y8/$Z$4),"") -> 1 | AA8: =IFERROR(COUNTIF(D8:X8,"A"),"") -> 0 | AB8: =IFERROR((AA8/$Z$4),"") -> 0 | AC8: =IFERROR(COUNTIF(D8:X8,"E"),"") -> 0 | AD8: =IFERROR((AC8/$Z$4),"") -> 0 | AE8: 2 | AF8: =C8 -> Daniel Elía Almonte Martínez | AG8: P | AH8: P | AI8: P | AJ8: P | AK8: P | AL8: P | AM8: P | AN8: P | AO8: P | AP8: P | AQ8: P | AR8: P | AU8: P | AV8: P | AW8: P | AY8: P | BA8: P | BB8: =IFERROR(COUNTIF(AG8:BA8,"P")+COUNTIF(AG8:BA8,"e")+COUNTIF(AG8:BA8,"t")-INT(COUNTIF(AG8:BA8,"e")/3)-INT(COUNTIF(AG8:BA8,"t")/3),"") -> 17 | BC8: =IFERROR(BB8/$BC$4,"") -> 1 | BD8: =IFERROR(COUNTIF(AG8:BA8,"A"),"") -> 0 | BE8: =IFERROR((BD8/$BC$4),"") -> 0 | BF8: =IFERROR(COUNTIF(AG8:BA8,"E"),"") -> 0 | BG8: =IFERROR((BF8/$BC$4),"") -> 0 | BN8: LENGUAS EXTRANJERAS:INGLÉS | BO8: FEBRERO | BP8: 2
A9: ='3A 2025 - 2026 DATOS DEL ESTUDI'!N6 -> 32743589 | B9: 3 | C9: ='3A 2025 - 2026 DATOS DEL ESTUDI'!B6 -> Isaac Ángeles Liriano | D9: P | E9: P | F9: P | G9: P | H9: P | Y9: =IFERROR(COUNTIF(D9:X9,"P")+COUNTIF(D9:X9,"e")+COUNTIF(D9:X9,"t")-INT(COUNTIF(D9:X9,"e")/3)-INT(COUNTIF(D9:X9,"t")/3),"") -> 5 | Z9: =IFERROR((Y9/$Z$4),"") -> 1 | AA9: =IFERROR(COUNTIF(D9:X9,"A"),"") -> 0 | AB9: =IFERROR((AA9/$Z$4),"") -> 0 | AC9: =IFERROR(COUNTIF(D9:X9,"E"),"") -> 0 | AD9: =IFERROR((AC9/$Z$4),"") -> 0 | AE9: 3 | AF9: =C9 -> Isaac Ángeles Liriano | AG9: P | AH9: P | AI9: P | AJ9: P | AK9: P | AL9: P | AM9: P | AN9: P | AO9: P | AP9: P | AQ9: P | AR9: P | AU9: P | AV9: P | AW9: P | AY9: P | BA9: P | BB9: =IFERROR(COUNTIF(AG9:BA9,"P")+COUNTIF(AG9:BA9,"e")+COUNTIF(AG9:BA9,"t")-INT(COUNTIF(AG9:BA9,"e")/3)-INT(COUNTIF(AG9:BA9,"t")/3),"") -> 17 | BC9: =IFERROR(BB9/$BC$4,"") -> 1 | BD9: =IFERROR(COUNTIF(AG9:BA9,"A"),"") -> 0 | BE9: =IFERROR((BD9/$BC$4),"") -> 0 | BF9: =IFERROR(COUNTIF(AG9:BA9,"E"),"") -> 0 | BG9: =IFERROR((BF9/$BC$4),"") -> 0 | BN9: LENGUAS EXTRANJERAS:FRANCÉS | BO9: MARZO | BP9: 3
A10: ='3A 2025 - 2026 DATOS DEL ESTUDI'!N7 -> 32899338 | B10: 4 | C10: ='3A 2025 - 2026 DATOS DEL ESTUDI'!B7 -> Melaniee Aquino Estrella | D10: P | E10: P | F10: P | G10: P | H10: P | Y10: =IFERROR(COUNTIF(D10:X10,"P")+COUNTIF(D10:X10,"e")+COUNTIF(D10:X10,"t")-INT(COUNTIF(D10:X10,"e")/3)-INT(COUNTIF(D10:X10,"t")/3),"") -> 5 | Z10: =IFERROR((Y10/$Z$4),"") -> 1 | AA10: =IFERROR(COUNTIF(D10:X10,"A"),"") -> 0 | AB10: =IFERROR((AA10/$Z$4),"") -> 0 | AC10: =IFERROR(COUNTIF(D10:X10,"E"),"") -> 0 | AD10: =IFERROR((AC10/$Z$4),"") -> 0 | AE10: 4 | AF10: =C10 -> Melaniee Aquino Estrella | AG10: P | AH10: P | AI10: P | AJ10: P | AK10: P | AL10: P | AM10: P | AN10: P | AO10: P | AP10: P | AQ10: P | AR10: P | AU10: P | AV10: P | AW10: P | AY10: P | BA10: P | BB10: =IFERROR(COUNTIF(AG10:BA10,"P")+COUNTIF(AG10:BA10,"e")+COUNTIF(AG10:BA10,"t")-INT(COUNTIF(AG10:BA10,"e")/3)-INT(COUNTIF(AG10:BA10,"t")/3),"") -> 17 | BC10: =IFERROR(BB10/$BC$4,"") -> 1 | BD10: =IFERROR(COUNTIF(AG10:BA10,"A"),"") -> 0 | BE10: =IFERROR((BD10/$BC$4),"") -> 0 | BF10: =IFERROR(COUNTIF(AG10:BA10,"E"),"") -> 0 | BG10: =IFERROR((BF10/$BC$4),"") -> 0 | BN10: MATEMÁTICA | BO10: ABRIL | BP10: 4
A11: ='3A 2025 - 2026 DATOS DEL ESTUDI'!N8 -> 33109621 | B11: 5 | C11: ='3A 2025 - 2026 DATOS DEL ESTUDI'!B8 -> Jennifer Asenjo De Los Santos TRANSFERIDA 10/12/25 | D11: P | E11: P | F11: P | G11: P | H11: P | Y11: =IFERROR(COUNTIF(D11:X11,"P")+COUNTIF(D11:X11,"e")+COUNTIF(D11:X11,"t")-INT(COUNTIF(D11:X11,"e")/3)-INT(COUNTIF(D11:X11,"t")/3),"") -> 5 | Z11: =IFERROR((Y11/$Z$4),"") -> 1 | AA11: =IFERROR(COUNTIF(D11:X11,"A"),"") -> 0 | AB11: =IFERROR((AA11/$Z$4),"") -> 0 | AC11: =IFERROR(COUNTIF(D11:X11,"E"),"") -> 0 | AD11: =IFERROR((AC11/$Z$4),"") -> 0 | AE11: 5 | AF11: =C11 -> Jennifer Asenjo De Los Santos TRANSFERIDA 10/12/25 | AG11: P | AH11: P | AI11: P | AJ11: P | AK11: P | AL11: P | AM11: P | AN11: P | AO11: P | AP11: P | AQ11: P | AR11: P | AU11: P | AV11: P | AW11: P | AY11: P | BA11: P | BB11: =IFERROR(COUNTIF(AG11:BA11,"P")+COUNTIF(AG11:BA11,"e")+COUNTIF(AG11:BA11,"t")-INT(COUNTIF(AG11:BA11,"e")/3)-INT(COUNTIF(AG11:BA11,"t")/3),"") -> 17 | BC11: =IFERROR(BB11/$BC$4,"") -> 1 | BD11: =IFERROR(COUNTIF(AG11:BA11,"A"),"") -> 0 | BE11: =IFERROR((BD11/$BC$4),"") -> 0 | BF11: =IFERROR(COUNTIF(AG11:BA11,"E"),"") -> 0 | BG11: =IFERROR((BF11/$BC$4),"") -> 0 | BN11: CIENCIAS SOCIALES | BO11: MAYO | BP11: 5
A12: ='3A 2025 - 2026 DATOS DEL ESTUDI'!N9 -> 32678295 | B12: 6 | C12: ='3A 2025 - 2026 DATOS DEL ESTUDI'!B9 -> Leshlie Crismayri Bautista Quezada | D12: P | E12: P | F12: P | G12: P | H12: P | Y12: =IFERROR(COUNTIF(D12:X12,"P")+COUNTIF(D12:X12,"e")+COUNTIF(D12:X12,"t")-INT(COUNTIF(D12:X12,"e")/3)-INT(COUNTIF(D12:X12,"t")/3),"") -> 5 | Z12: =IFERROR((Y12/$Z$4),"") -> 1 | AA12: =IFERROR(COUNTIF(D12:X12,"A"),"") -> 0 | AB12: =IFERROR((AA12/$Z$4),"") -> 0 | AC12: =IFERROR(COUNTIF(D12:X12,"E"),"") -> 0 | AD12: =IFERROR((AC12/$Z$4),"") -> 0 | AE12: 6 | AF12: =C12 -> Leshlie Crismayri Bautista Quezada | AG12: P | AH12: P | AI12: P | AJ12: P | AK12: P | AL12: P | AM12: P | AN12: P | AO12: P | AP12: P | AQ12: P | AR12: P | AU12: P | AV12: P | AW12: P | AY12: P | BA12: P | BB12: =IFERROR(COUNTIF(AG12:BA12,"P")+COUNTIF(AG12:BA12,"e")+COUNTIF(AG12:BA12,"t")-INT(COUNTIF(AG12:BA12,"e")/3)-INT(COUNTIF(AG12:BA12,"t")/3),"") -> 17 | BC12: =IFERROR(BB12/$BC$4,"") -> 1 | BD12: =IFERROR(COUNTIF(AG12:BA12,"A"),"") -> 0 | BE12: =IFERROR((BD12/$BC$4),"") -> 0 | BF12: =IFERROR(COUNTIF(AG12:BA12,"E"),"") -> 0 | BG12: =IFERROR((BF12/$BC$4),"") -> 0 | BN12: CIENCIAS DE LA NATURALEZA: CIENCIAS FÍSICAS | BO12: JUNIO | BP12: 6
A13: ='3A 2025 - 2026 DATOS DEL ESTUDI'!N10 -> 33224927 | B13: 7 | C13: ='3A 2025 - 2026 DATOS DEL ESTUDI'!B10 -> Gilber Bello Silva | D13: P | E13: P | F13: P | G13: P | H13: P | Y13: =IFERROR(COUNTIF(D13:X13,"P")+COUNTIF(D13:X13,"e")+COUNTIF(D13:X13,"t")-INT(COUNTIF(D13:X13,"e")/3)-INT(COUNTIF(D13:X13,"t")/3),"") -> 5 | Z13: =IFERROR((Y13/$Z$4),"") -> 1 | AA13: =IFERROR(COUNTIF(D13:X13,"A"),"") -> 0 | AB13: =IFERROR((AA13/$Z$4),"") -> 0 | AC13: =IFERROR(COUNTIF(D13:X13,"E"),"") -> 0 | AD13: =IFERROR((AC13/$Z$4),"") -> 0 | AE13: 7 | AF13: =C13 -> Gilber Bello Silva | AG13: P | AH13: P | AI13: P | AJ13: P | AK13: P | AL13: P | AM13: P | AN13: P | AO13: P | AP13: P | AQ13: P | AR13: P | AU13: P | AV13: P | AW13: P | AY13: P | BA13: P | BB13: =IFERROR(COUNTIF(AG13:BA13,"P")+COUNTIF(AG13:BA13,"e")+COUNTIF(AG13:BA13,"t")-INT(COUNTIF(AG13:BA13,"e")/3)-INT(COUNTIF(AG13:BA13,"t")/3),"") -> 17 | BC13: =IFERROR(BB13/$BC$4,"") -> 1 | BD13: =IFERROR(COUNTIF(AG13:BA13,"A"),"") -> 0 | BE13: =IFERROR((BD13/$BC$4),"") -> 0 | BF13: =IFERROR(COUNTIF(AG13:BA13,"E"),"") -> 0 | BG13: =IFERROR((BF13/$BC$4),"") -> 0 | BN13: EDUCACIÓN ARTÍSTICA | BO13: JULIO | BP13: 7
A14: ='3A 2025 - 2026 DATOS DEL ESTUDI'!N11 -> 6783589 | B14: 8 | C14: ='3A 2025 - 2026 DATOS DEL ESTUDI'!B11 -> Sherlyn Mariel Bernabel Lora | D14: P | E14: P | F14: P | G14: P | H14: P | Y14: =IFERROR(COUNTIF(D14:X14,"P")+COUNTIF(D14:X14,"e")+COUNTIF(D14:X14,"t")-INT(COUNTIF(D14:X14,"e")/3)-INT(COUNTIF(D14:X14,"t")/3),"") -> 5 | Z14: =IFERROR((Y14/$Z$4),"") -> 1 | AA14: =IFERROR(COUNTIF(D14:X14,"A"),"") -> 0 | AB14: =IFERROR((AA14/$Z$4),"") -> 0 | AC14: =IFERROR(COUNTIF(D14:X14,"E"),"") -> 0 | AD14: =IFERROR((AC14/$Z$4),"") -> 0 | AE14: 8 | AF14: =C14 -> Sherlyn Mariel Bernabel Lora | AG14: P | AH14: P | AI14: P | AJ14: P | AK14: P | AL14: P | AM14: P | AN14: P | AO14: P | AP14: P | AQ14: P | AR14: P | AU14: P | AV14: P | AW14: P | AY14: P | BA14: P | BB14: =IFERROR(COUNTIF(AG14:BA14,"P")+COUNTIF(AG14:BA14,"e")+COUNTIF(AG14:BA14,"t")-INT(COUNTIF(AG14:BA14,"e")/3)-INT(COUNTIF(AG14:BA14,"t")/3),"") -> 17 | BC14: =IFERROR(BB14/$BC$4,"") -> 1 | BD14: =IFERROR(COUNTIF(AG14:BA14,"A"),"") -> 0 | BE14: =IFERROR((BD14/$BC$4),"") -> 0 | BF14: =IFERROR(COUNTIF(AG14:BA14,"E"),"") -> 0 | BG14: =IFERROR((BF14/$BC$4),"") -> 0 | BN14: EDUCACIÓN FÍSICA | BO14: AGOSTO | BP14: 8
A15: ='3A 2025 - 2026 DATOS DEL ESTUDI'!N12 -> 7117826 | B15: 9 | C15: ='3A 2025 - 2026 DATOS DEL ESTUDI'!B12 -> Erleen Brito Castillo | D15: P | E15: P | F15: P | G15: P | H15: P | Y15: =IFERROR(COUNTIF(D15:X15,"P")+COUNTIF(D15:X15,"e")+COUNTIF(D15:X15,"t")-INT(COUNTIF(D15:X15,"e")/3)-INT(COUNTIF(D15:X15,"t")/3),"") -> 5 | Z15: =IFERROR((Y15/$Z$4),"") -> 1 | AA15: =IFERROR(COUNTIF(D15:X15,"A"),"") -> 0 | AB15: =IFERROR((AA15/$Z$4),"") -> 0 | AC15: =IFERROR(COUNTIF(D15:X15,"E"),"") -> 0 | AD15: =IFERROR((AC15/$Z$4),"") -> 0 | AE15: 9 | AF15: =C15 -> Erleen Brito Castillo | AG15: P | AH15: P | AI15: P | AJ15: P | AK15: P | AL15: P | AM15: P | AN15: P | AO15: P | AP15: P | AQ15: P | AR15: P | AU15: P | AV15: P | AW15: P | AY15: P | BA15: P | BB15: =IFERROR(COUNTIF(AG15:BA15,"P")+COUNTIF(AG15:BA15,"e")+COUNTIF(AG15:BA15,"t")-INT(COUNTIF(AG15:BA15,"e")/3)-INT(COUNTIF(AG15:BA15,"t")/3),"") -> 17 | BC15: =IFERROR(BB15/$BC$4,"") -> 1 | BD15: =IFERROR(COUNTIF(AG15:BA15,"A"),"") -> 0 | BE15: =IFERROR((BD15/$BC$4),"") -> 0 | BF15: =IFERROR(COUNTIF(AG15:BA15,"E"),"") -> 0 | BG15: =IFERROR((BF15/$BC$4),"") -> 0 | BN15: FORMACIÓN INTEGRAL HUMANA Y RELIGIOSA | BO15: SEPTIEMBRE | BP15: 9
A16: ='3A 2025 - 2026 DATOS DEL ESTUDI'!N13 -> 7042227 | B16: 10 | C16: ='3A 2025 - 2026 DATOS DEL ESTUDI'!B13 -> Brianny Caraballo Guzmán | D16: P | E16: P | F16: P | G16: P | H16: P | Y16: =IFERROR(COUNTIF(D16:X16,"P")+COUNTIF(D16:X16,"e")+COUNTIF(D16:X16,"t")-INT(COUNTIF(D16:X16,"e")/3)-INT(COUNTIF(D16:X16,"t")/3),"") -> 5 | Z16: =IFERROR((Y16/$Z$4),"") -> 1 | AA16: =IFERROR(COUNTIF(D16:X16,"A"),"") -> 0 | AB16: =IFERROR((AA16/$Z$4),"") -> 0 | AC16: =IFERROR(COUNTIF(D16:X16,"E"),"") -> 0 | AD16: =IFERROR((AC16/$Z$4),"") -> 0 | AE16: 10 | AF16: =C16 -> Brianny Caraballo Guzmán | AG16: P | AH16: P | AI16: P | AJ16: P | AK16: P | AL16: P | AM16: P | AN16: P | AO16: P | AP16: P | AQ16: P | AR16: P | AU16: P | AV16: P | AW16: P | AY16: P | BA16: P | BB16: =IFERROR(COUNTIF(AG16:BA16,"P")+COUNTIF(AG16:BA16,"e")+COUNTIF(AG16:BA16,"t")-INT(COUNTIF(AG16:BA16,"e")/3)-INT(COUNTIF(AG16:BA16,"t")/3),"") -> 17 | BC16: =IFERROR(BB16/$BC$4,"") -> 1 | BD16: =IFERROR(COUNTIF(AG16:BA16,"A"),"") -> 0 | BE16: =IFERROR((BD16/$BC$4),"") -> 0 | BF16: =IFERROR(COUNTIF(AG16:BA16,"E"),"") -> 0 | BG16: =IFERROR((BF16/$BC$4),"") -> 0 | BO16: OCTUBRE | BP16: 10
A17: ='3A 2025 - 2026 DATOS DEL ESTUDI'!N14 -> 32626669 | B17: 11 | C17: ='3A 2025 - 2026 DATOS DEL ESTUDI'!B14 -> Scarlet Castillo | D17: P | E17: P | F17: P | G17: P | H17: P | Y17: =IFERROR(COUNTIF(D17:X17,"P")+COUNTIF(D17:X17,"e")+COUNTIF(D17:X17,"t")-INT(COUNTIF(D17:X17,"e")/3)-INT(COUNTIF(D17:X17,"t")/3),"") -> 5 | Z17: =IFERROR((Y17/$Z$4),"") -> 1 | AA17: =IFERROR(COUNTIF(D17:X17,"A"),"") -> 0 | AB17: =IFERROR((AA17/$Z$4),"") -> 0 | AC17: =IFERROR(COUNTIF(D17:X17,"E"),"") -> 0 | AD17: =IFERROR((AC17/$Z$4),"") -> 0 | AE17: 11 | AF17: =C17 -> Scarlet Castillo | AG17: P | AH17: P | AI17: P | AJ17: P | AK17: P | AL17: P | AM17: P | AN17: P | AO17: P | AP17: P | AQ17: P | AR17: P | AU17: P | AV17: P | AW17: P | AY17: P | BA17: P | BB17: =IFERROR(COUNTIF(AG17:BA17,"P")+COUNTIF(AG17:BA17,"e")+COUNTIF(AG17:BA17,"t")-INT(COUNTIF(AG17:BA17,"e")/3)-INT(COUNTIF(AG17:BA17,"t")/3),"") -> 17 | BC17: =IFERROR(BB17/$BC$4,"") -> 1 | BD17: =IFERROR(COUNTIF(AG17:BA17,"A"),"") -> 0 | BE17: =IFERROR((BD17/$BC$4),"") -> 0 | BF17: =IFERROR(COUNTIF(AG17:BA17,"E"),"") -> 0 | BG17: =IFERROR((BF17/$BC$4),"") -> 0 | BO17: NOVIEMBRE | BP17: 11
A18: ='3A 2025 - 2026 DATOS DEL ESTUDI'!N15 -> 33016326 | B18: 12 | C18: ='3A 2025 - 2026 DATOS DEL ESTUDI'!B15 -> Yarselin Cruz Peña | D18: P | E18: P | F18: P | G18: P | H18: P | Y18: =IFERROR(COUNTIF(D18:X18,"P")+COUNTIF(D18:X18,"e")+COUNTIF(D18:X18,"t")-INT(COUNTIF(D18:X18,"e")/3)-INT(COUNTIF(D18:X18,"t")/3),"") -> 5 | Z18: =IFERROR((Y18/$Z$4),"") -> 1 | AA18: =IFERROR(COUNTIF(D18:X18,"A"),"") -> 0 | AB18: =IFERROR((AA18/$Z$4),"") -> 0 | AC18: =IFERROR(COUNTIF(D18:X18,"E"),"") -> 0 | AD18: =IFERROR((AC18/$Z$4),"") -> 0 | AE18: 12 | AF18: =C18 -> Yarselin Cruz Peña | AG18: P | AH18: P | AI18: P | AJ18: P | AK18: P | AL18: P | AM18: P | AN18: P | AO18: P | AP18: P | AQ18: P | AR18: P | AU18: P | AV18: P | AW18: P | AY18: P | BA18: P | BB18: =IFERROR(COUNTIF(AG18:BA18,"P")+COUNTIF(AG18:BA18,"e")+COUNTIF(AG18:BA18,"t")-INT(COUNTIF(AG18:BA18,"e")/3)-INT(COUNTIF(AG18:BA18,"t")/3),"") -> 17 | BC18: =IFERROR(BB18/$BC$4,"") -> 1 | BD18: =IFERROR(COUNTIF(AG18:BA18,"A"),"") -> 0 | BE18: =IFERROR((BD18/$BC$4),"") -> 0 | BF18: =IFERROR(COUNTIF(AG18:BA18,"E"),"") -> 0 | BG18: =IFERROR((BF18/$BC$4),"") -> 0 | BO18: DICIEMBRE | BP18: 12
A19: ='3A 2025 - 2026 DATOS DEL ESTUDI'!N16 -> 32387390 | B19: 13 | C19: ='3A 2025 - 2026 DATOS DEL ESTUDI'!B16 -> Fernando José Díaz Fernández | D19: P | E19: P | F19: P | G19: P | H19: P | Y19: =IFERROR(COUNTIF(D19:X19,"P")+COUNTIF(D19:X19,"e")+COUNTIF(D19:X19,"t")-INT(COUNTIF(D19:X19,"e")/3)-INT(COUNTIF(D19:X19,"t")/3),"") -> 5 | Z19: =IFERROR((Y19/$Z$4),"") -> 1 | AA19: =IFERROR(COUNTIF(D19:X19,"A"),"") -> 0 | AB19: =IFERROR((AA19/$Z$4),"") -> 0 | AC19: =IFERROR(COUNTIF(D19:X19,"E"),"") -> 0 | AD19: =IFERROR((AC19/$Z$4),"") -> 0 | AE19: 13 | AF19: =C19 -> Fernando José Díaz Fernández | AG19: P | AH19: P | AI19: P | AJ19: P | AK19: P | AL19: P | AM19: P | AN19: P | AO19: P | AP19: P | AQ19: P | AR19: P | AU19: P | AV19: P | AW19: P | AY19: P | BA19: P | BB19: =IFERROR(COUNTIF(AG19:BA19,"P")+COUNTIF(AG19:BA19,"e")+COUNTIF(AG19:BA19,"t")-INT(COUNTIF(AG19:BA19,"e")/3)-INT(COUNTIF(AG19:BA19,"t")/3),"") -> 17 | BC19: =IFERROR(BB19/$BC$4,"") -> 1 | BD19: =IFERROR(COUNTIF(AG19:BA19,"A"),"") -> 0 | BE19: =IFERROR((BD19/$BC$4),"") -> 0 | BF19: =IFERROR(COUNTIF(AG19:BA19,"E"),"") -> 0 | BG19: =IFERROR((BF19/$BC$4),"") -> 0 | BP19: 13
A20: ='3A 2025 - 2026 DATOS DEL ESTUDI'!N17 -> 27198412 | B20: 14 | C20: ='3A 2025 - 2026 DATOS DEL ESTUDI'!B17 -> Scarlett Espinal Estéves | D20: P | E20: P | F20: P | G20: P | H20: P | Y20: =IFERROR(COUNTIF(D20:X20,"P")+COUNTIF(D20:X20,"e")+COUNTIF(D20:X20,"t")-INT(COUNTIF(D20:X20,"e")/3)-INT(COUNTIF(D20:X20,"t")/3),"") -> 5 | Z20: =IFERROR((Y20/$Z$4),"") -> 1 | AA20: =IFERROR(COUNTIF(D20:X20,"A"),"") -> 0 | AB20: =IFERROR((AA20/$Z$4),"") -> 0 | AC20: =IFERROR(COUNTIF(D20:X20,"E"),"") -> 0 | AD20: =IFERROR((AC20/$Z$4),"") -> 0 | AE20: 14 | AF20: =C20 -> Scarlett Espinal Estéves | AG20: P | AH20: P | AI20: P | AJ20: P | AK20: P | AL20: P | AM20: P | AN20: P | AO20: P | AP20: P | AQ20: P | AR20: P | AU20: P | AV20: P | AW20: P | AY20: P | BA20: P | BB20: =IFERROR(COUNTIF(AG20:BA20,"P")+COUNTIF(AG20:BA20,"e")+COUNTIF(AG20:BA20,"t")-INT(COUNTIF(AG20:BA20,"e")/3)-INT(COUNTIF(AG20:BA20,"t")/3),"") -> 17 | BC20: =IFERROR(BB20/$BC$4,"") -> 1 | BD20: =IFERROR(COUNTIF(AG20:BA20,"A"),"") -> 0 | BE20: =IFERROR((BD20/$BC$4),"") -> 0 | BF20: =IFERROR(COUNTIF(AG20:BA20,"E"),"") -> 0 | BG20: =IFERROR((BF20/$BC$4),"") -> 0 | BP20: 14
A21: ='3A 2025 - 2026 DATOS DEL ESTUDI'!N18 -> 33382609 | B21: 15 | C21: ='3A 2025 - 2026 DATOS DEL ESTUDI'!B18 -> José Manuel Estrella | D21: P | E21: P | F21: P | G21: P | H21: P | Y21: =IFERROR(COUNTIF(D21:X21,"P")+COUNTIF(D21:X21,"e")+COUNTIF(D21:X21,"t")-INT(COUNTIF(D21:X21,"e")/3)-INT(COUNTIF(D21:X21,"t")/3),"") -> 5 | Z21: =IFERROR((Y21/$Z$4),"") -> 1 | AA21: =IFERROR(COUNTIF(D21:X21,"A"),"") -> 0 | AB21: =IFERROR((AA21/$Z$4),"") -> 0 | AC21: =IFERROR(COUNTIF(D21:X21,"E"),"") -> 0 | AD21: =IFERROR((AC21/$Z$4),"") -> 0 | AE21: 15 | AF21: =C21 -> José Manuel Estrella | AG21: P | AH21: P | AI21: P | AJ21: P | AK21: P | AL21: P | AM21: P | AN21: P | AO21: P | AP21: P | AQ21: P | AR21: P | AU21: P | AV21: P | AW21: P | AY21: P | BA21: P | BB21: =IFERROR(COUNTIF(AG21:BA21,"P")+COUNTIF(AG21:BA21,"e")+COUNTIF(AG21:BA21,"t")-INT(COUNTIF(AG21:BA21,"e")/3)-INT(COUNTIF(AG21:BA21,"t")/3),"") -> 17 | BC21: =IFERROR(BB21/$BC$4,"") -> 1 | BD21: =IFERROR(COUNTIF(AG21:BA21,"A"),"") -> 0 | BE21: =IFERROR((BD21/$BC$4),"") -> 0 | BF21: =IFERROR(COUNTIF(AG21:BA21,"E"),"") -> 0 | BG21: =IFERROR((BF21/$BC$4),"") -> 0 | BP21: 15
A22: ='3A 2025 - 2026 DATOS DEL ESTUDI'!N19 -> 32745811 | B22: 16 | C22: ='3A 2025 - 2026 DATOS DEL ESTUDI'!B19 -> Misael Starberk Ferreras Pérez | D22: P | E22: P | F22: P | G22: P | H22: P | Y22: =IFERROR(COUNTIF(D22:X22,"P")+COUNTIF(D22:X22,"e")+COUNTIF(D22:X22,"t")-INT(COUNTIF(D22:X22,"e")/3)-INT(COUNTIF(D22:X22,"t")/3),"") -> 5 | Z22: =IFERROR((Y22/$Z$4),"") -> 1 | AA22: =IFERROR(COUNTIF(D22:X22,"A"),"") -> 0 | AB22: =IFERROR((AA22/$Z$4),"") -> 0 | AC22: =IFERROR(COUNTIF(D22:X22,"E"),"") -> 0 | AD22: =IFERROR((AC22/$Z$4),"") -> 0 | AE22: 16 | AF22: =C22 -> Misael Starberk Ferreras Pérez | AG22: P | AH22: P | AI22: P | AJ22: P | AK22: P | AL22: P | AM22: P | AN22: P | AO22: P | AP22: P | AQ22: P | AR22: P | AU22: P | AV22: P | AW22: P | AY22: P | BA22: P | BB22: =IFERROR(COUNTIF(AG22:BA22,"P")+COUNTIF(AG22:BA22,"e")+COUNTIF(AG22:BA22,"t")-INT(COUNTIF(AG22:BA22,"e")/3)-INT(COUNTIF(AG22:BA22,"t")/3),"") -> 17 | BC22: =IFERROR(BB22/$BC$4,"") -> 1 | BD22: =IFERROR(COUNTIF(AG22:BA22,"A"),"") -> 0 | BE22: =IFERROR((BD22/$BC$4),"") -> 0 | BF22: =IFERROR(COUNTIF(AG22:BA22,"E"),"") -> 0 | BG22: =IFERROR((BF22/$BC$4),"") -> 0 | BP22: 16
A23: ='3A 2025 - 2026 DATOS DEL ESTUDI'!N20 -> 6739413 | B23: 17 | C23: ='3A 2025 - 2026 DATOS DEL ESTUDI'!B20 -> Ruth Esther Fernández Rodríguez | D23: P | E23: P | F23: P | G23: P | H23: P | Y23: =IFERROR(COUNTIF(D23:X23,"P")+COUNTIF(D23:X23,"e")+COUNTIF(D23:X23,"t")-INT(COUNTIF(D23:X23,"e")/3)-INT(COUNTIF(D23:X23,"t")/3),"") -> 5 | Z23: =IFERROR((Y23/$Z$4),"") -> 1 | AA23: =IFERROR(COUNTIF(D23:X23,"A"),"") -> 0 | AB23: =IFERROR((AA23/$Z$4),"") -> 0 | AC23: =IFERROR(COUNTIF(D23:X23,"E"),"") -> 0 | AD23: =IFERROR((AC23/$Z$4),"") -> 0 | AE23: 17 | AF23: =C23 -> Ruth Esther Fernández Rodríguez | AG23: P | AH23: P | AI23: P | AJ23: P | AK23: P | AL23: P | AM23: P | AN23: P | AO23: P | AP23: P | AQ23: P | AR23: P | AU23: P | AV23: P | AW23: P | AY23: P | BA23: P | BB23: =IFERROR(COUNTIF(AG23:BA23,"P")+COUNTIF(AG23:BA23,"e")+COUNTIF(AG23:BA23,"t")-INT(COUNTIF(AG23:BA23,"e")/3)-INT(COUNTIF(AG23:BA23,"t")/3),"") -> 17 | BC23: =IFERROR(BB23/$BC$4,"") -> 1 | BD23: =IFERROR(COUNTIF(AG23:BA23,"A"),"") -> 0 | BE23: =IFERROR((BD23/$BC$4),"") -> 0 | BF23: =IFERROR(COUNTIF(AG23:BA23,"E"),"") -> 0 | BG23: =IFERROR((BF23/$BC$4),"") -> 0 | BP23: 17
A24: ='3A 2025 - 2026 DATOS DEL ESTUDI'!N21 -> 32812732 | B24: 18 | C24: ='3A 2025 - 2026 DATOS DEL ESTUDI'!B21 -> Discairy Filpo Estrella | D24: P | E24: P | F24: P | G24: P | H24: P | Y24: =IFERROR(COUNTIF(D24:X24,"P")+COUNTIF(D24:X24,"e")+COUNTIF(D24:X24,"t")-INT(COUNTIF(D24:X24,"e")/3)-INT(COUNTIF(D24:X24,"t")/3),"") -> 5 | Z24: =IFERROR((Y24/$Z$4),"") -> 1 | AA24: =IFERROR(COUNTIF(D24:X24,"A"),"") -> 0 | AB24: =IFERROR((AA24/$Z$4),"") -> 0 | AC24: =IFERROR(COUNTIF(D24:X24,"E"),"") -> 0 | AD24: =IFERROR((AC24/$Z$4),"") -> 0 | AE24: 18 | AF24: =C24 -> Discairy Filpo Estrella | AG24: P | AH24: P | AI24: P | AJ24: P | AK24: P | AL24: P | AM24: P | AN24: P | AO24: P | AP24: P | AQ24: P | AR24: P | AU24: P | AV24: P | AW24: P | AY24: P | BA24: P | BB24: =IFERROR(COUNTIF(AG24:BA24,"P")+COUNTIF(AG24:BA24,"e")+COUNTIF(AG24:BA24,"t")-INT(COUNTIF(AG24:BA24,"e")/3)-INT(COUNTIF(AG24:BA24,"t")/3),"") -> 17 | BC24: =IFERROR(BB24/$BC$4,"") -> 1 | BD24: =IFERROR(COUNTIF(AG24:BA24,"A"),"") -> 0 | BE24: =IFERROR((BD24/$BC$4),"") -> 0 | BF24: =IFERROR(COUNTIF(AG24:BA24,"E"),"") -> 0 | BG24: =IFERROR((BF24/$BC$4),"") -> 0 | BP24: 18
A25: ='3A 2025 - 2026 DATOS DEL ESTUDI'!N22 -> 32529336 | B25: 19 | C25: ='3A 2025 - 2026 DATOS DEL ESTUDI'!B22 -> Alexis Enmanuel Gil Sánchez | D25: P | E25: P | F25: P | G25: P | H25: P | Y25: =IFERROR(COUNTIF(D25:X25,"P")+COUNTIF(D25:X25,"e")+COUNTIF(D25:X25,"t")-INT(COUNTIF(D25:X25,"e")/3)-INT(COUNTIF(D25:X25,"t")/3),"") -> 5 | Z25: =IFERROR((Y25/$Z$4),"") -> 1 | AA25: =IFERROR(COUNTIF(D25:X25,"A"),"") -> 0 | AB25: =IFERROR((AA25/$Z$4),"") -> 0 | AC25: =IFERROR(COUNTIF(D25:X25,"E"),"") -> 0 | AD25: =IFERROR((AC25/$Z$4),"") -> 0 | AE25: 19 | AF25: =C25 -> Alexis Enmanuel Gil Sánchez | AG25: P | AH25: P | AI25: P | AJ25: P | AK25: P | AL25: P | AM25: P | AN25: P | AO25: P | AP25: P | AQ25: P | AR25: P | AU25: P | AV25: P | AW25: P | AY25: P | BA25: P | BB25: =IFERROR(COUNTIF(AG25:BA25,"P")+COUNTIF(AG25:BA25,"e")+COUNTIF(AG25:BA25,"t")-INT(COUNTIF(AG25:BA25,"e")/3)-INT(COUNTIF(AG25:BA25,"t")/3),"") -> 17 | BC25: =IFERROR(BB25/$BC$4,"") -> 1 | BD25: =IFERROR(COUNTIF(AG25:BA25,"A"),"") -> 0 | BE25: =IFERROR((BD25/$BC$4),"") -> 0 | BF25: =IFERROR(COUNTIF(AG25:BA25,"E"),"") -> 0 | BG25: =IFERROR((BF25/$BC$4),"") -> 0 | BP25: 19
A26: ='3A 2025 - 2026 DATOS DEL ESTUDI'!N23 -> 22047916 | B26: 20 | C26: ='3A 2025 - 2026 DATOS DEL ESTUDI'!B23 -> Ayendy Jesús Guzmán | D26: P | E26: P | F26: P | G26: P | H26: P | Y26: =IFERROR(COUNTIF(D26:X26,"P")+COUNTIF(D26:X26,"e")+COUNTIF(D26:X26,"t")-INT(COUNTIF(D26:X26,"e")/3)-INT(COUNTIF(D26:X26,"t")/3),"") -> 5 | Z26: =IFERROR((Y26/$Z$4),"") -> 1 | AA26: =IFERROR(COUNTIF(D26:X26,"A"),"") -> 0 | AB26: =IFERROR((AA26/$Z$4),"") -> 0 | AC26: =IFERROR(COUNTIF(D26:X26,"E"),"") -> 0 | AD26: =IFERROR((AC26/$Z$4),"") -> 0 | AE26: 20 | AF26: =C26 -> Ayendy Jesús Guzmán | AG26: P | AH26: P | AI26: P | AJ26: P | AK26: P | AL26: P | AM26: P | AN26: P | AO26: P | AP26: P | AQ26: P | AR26: P | AU26: P | AV26: P | AW26: P | AY26: P | BA26: P | BB26: =IFERROR(COUNTIF(AG26:BA26,"P")+COUNTIF(AG26:BA26,"e")+COUNTIF(AG26:BA26,"t")-INT(COUNTIF(AG26:BA26,"e")/3)-INT(COUNTIF(AG26:BA26,"t")/3),"") -> 17 | BC26: =IFERROR(BB26/$BC$4,"") -> 1 | BD26: =IFERROR(COUNTIF(AG26:BA26,"A"),"") -> 0 | BE26: =IFERROR((BD26/$BC$4),"") -> 0 | BF26: =IFERROR(COUNTIF(AG26:BA26,"E"),"") -> 0 | BG26: =IFERROR((BF26/$BC$4),"") -> 0 | BP26: 20
A27: ='3A 2025 - 2026 DATOS DEL ESTUDI'!N24 -> 32387479 | B27: 21 | C27: ='3A 2025 - 2026 DATOS DEL ESTUDI'!B24 -> Yassir Hernández Disla | D27: P | E27: P | F27: P | G27: P | H27: P | Y27: =IFERROR(COUNTIF(D27:X27,"P")+COUNTIF(D27:X27,"e")+COUNTIF(D27:X27,"t")-INT(COUNTIF(D27:X27,"e")/3)-INT(COUNTIF(D27:X27,"t")/3),"") -> 5 | Z27: =IFERROR((Y27/$Z$4),"") -> 1 | AA27: =IFERROR(COUNTIF(D27:X27,"A"),"") -> 0 | AB27: =IFERROR((AA27/$Z$4),"") -> 0 | AC27: =IFERROR(COUNTIF(D27:X27,"E"),"") -> 0 | AD27: =IFERROR((AC27/$Z$4),"") -> 0 | AE27: 21 | AF27: =C27 -> Yassir Hernández Disla | AG27: P | AH27: P | AI27: P | AJ27: P | AK27: P | AL27: P | AM27: P | AN27: P | AO27: P | AP27: P | AQ27: P | AR27: P | AU27: P | AV27: P | AW27: P | AY27: P | BA27: P | BB27: =IFERROR(COUNTIF(AG27:BA27,"P")+COUNTIF(AG27:BA27,"e")+COUNTIF(AG27:BA27,"t")-INT(COUNTIF(AG27:BA27,"e")/3)-INT(COUNTIF(AG27:BA27,"t")/3),"") -> 17 | BC27: =IFERROR(BB27/$BC$4,"") -> 1 | BD27: =IFERROR(COUNTIF(AG27:BA27,"A"),"") -> 0 | BE27: =IFERROR((BD27/$BC$4),"") -> 0 | BF27: =IFERROR(COUNTIF(AG27:BA27,"E"),"") -> 0 | BG27: =IFERROR((BF27/$BC$4),"") -> 0 | BP27: 21
A28: ='3A 2025 - 2026 DATOS DEL ESTUDI'!N25 -> 6635033 | B28: 22 | C28: ='3A 2025 - 2026 DATOS DEL ESTUDI'!B25 -> Yadiel Jiménez Betances | D28: P | E28: P | F28: P | G28: P | H28: P | Y28: =IFERROR(COUNTIF(D28:X28,"P")+COUNTIF(D28:X28,"e")+COUNTIF(D28:X28,"t")-INT(COUNTIF(D28:X28,"e")/3)-INT(COUNTIF(D28:X28,"t")/3),"") -> 5 | Z28: =IFERROR((Y28/$Z$4),"") -> 1 | AA28: =IFERROR(COUNTIF(D28:X28,"A"),"") -> 0 | AB28: =IFERROR((AA28/$Z$4),"") -> 0 | AC28: =IFERROR(COUNTIF(D28:X28,"E"),"") -> 0 | AD28: =IFERROR((AC28/$Z$4),"") -> 0 | AE28: 22 | AF28: =C28 -> Yadiel Jiménez Betances | AG28: P | AH28: P | AI28: P | AJ28: P | AK28: P | AL28: P | AM28: P | AN28: P | AO28: P | AP28: P | AQ28: P | AR28: P | AU28: P | AV28: P | AW28: P | AY28: P | BA28: P | BB28: =IFERROR(COUNTIF(AG28:BA28,"P")+COUNTIF(AG28:BA28,"e")+COUNTIF(AG28:BA28,"t")-INT(COUNTIF(AG28:BA28,"e")/3)-INT(COUNTIF(AG28:BA28,"t")/3),"") -> 17 | BC28: =IFERROR(BB28/$BC$4,"") -> 1 | BD28: =IFERROR(COUNTIF(AG28:BA28,"A"),"") -> 0 | BE28: =IFERROR((BD28/$BC$4),"") -> 0 | BF28: =IFERROR(COUNTIF(AG28:BA28,"E"),"") -> 0 | BG28: =IFERROR((BF28/$BC$4),"") -> 0 | BP28: 22
A29: ='3A 2025 - 2026 DATOS DEL ESTUDI'!N26 -> 32857385 | B29: 23 | C29: ='3A 2025 - 2026 DATOS DEL ESTUDI'!B26 -> Yamel Mella Aquino | D29: P | E29: P | F29: P | G29: P | H29: P | Y29: =IFERROR(COUNTIF(D29:X29,"P")+COUNTIF(D29:X29,"e")+COUNTIF(D29:X29,"t")-INT(COUNTIF(D29:X29,"e")/3)-INT(COUNTIF(D29:X29,"t")/3),"") -> 5 | Z29: =IFERROR((Y29/$Z$4),"") -> 1 | AA29: =IFERROR(COUNTIF(D29:X29,"A"),"") -> 0 | AB29: =IFERROR((AA29/$Z$4),"") -> 0 | AC29: =IFERROR(COUNTIF(D29:X29,"E"),"") -> 0 | AD29: =IFERROR((AC29/$Z$4),"") -> 0 | AE29: 23 | AF29: =C29 -> Yamel Mella Aquino | AG29: P | AH29: P | AI29: P | AJ29: P | AK29: P | AL29: P | AM29: P | AN29: P | AO29: P | AP29: P | AQ29: P | AR29: P | AU29: P | AV29: P | AW29: P | AY29: P | BA29: P | BB29: =IFERROR(COUNTIF(AG29:BA29,"P")+COUNTIF(AG29:BA29,"e")+COUNTIF(AG29:BA29,"t")-INT(COUNTIF(AG29:BA29,"e")/3)-INT(COUNTIF(AG29:BA29,"t")/3),"") -> 17 | BC29: =IFERROR(BB29/$BC$4,"") -> 1 | BD29: =IFERROR(COUNTIF(AG29:BA29,"A"),"") -> 0 | BE29: =IFERROR((BD29/$BC$4),"") -> 0 | BF29: =IFERROR(COUNTIF(AG29:BA29,"E"),"") -> 0 | BG29: =IFERROR((BF29/$BC$4),"") -> 0 | BP29: 23
A30: ='3A 2025 - 2026 DATOS DEL ESTUDI'!N27 -> 6396255 | B30: 24 | C30: ='3A 2025 - 2026 DATOS DEL ESTUDI'!B27 -> Sariely Del Carmen Mena Chávez | D30: P | E30: P | F30: P | G30: P | H30: P | Y30: =IFERROR(COUNTIF(D30:X30,"P")+COUNTIF(D30:X30,"e")+COUNTIF(D30:X30,"t")-INT(COUNTIF(D30:X30,"e")/3)-INT(COUNTIF(D30:X30,"t")/3),"") -> 5 | Z30: =IFERROR((Y30/$Z$4),"") -> 1 | AA30: =IFERROR(COUNTIF(D30:X30,"A"),"") -> 0 | AB30: =IFERROR((AA30/$Z$4),"") -> 0 | AC30: =IFERROR(COUNTIF(D30:X30,"E"),"") -> 0 | AD30: =IFERROR((AC30/$Z$4),"") -> 0 | AE30: 24 | AF30: =C30 -> Sariely Del Carmen Mena Chávez | AG30: P | AH30: P | AI30: P | AJ30: P | AK30: P | AL30: P | AM30: P | AN30: P | AO30: P | AP30: P | AQ30: P | AR30: P | AU30: P | AV30: P | AW30: P | AY30: P | BA30: P | BB30: =IFERROR(COUNTIF(AG30:BA30,"P")+COUNTIF(AG30:BA30,"e")+COUNTIF(AG30:BA30,"t")-INT(COUNTIF(AG30:BA30,"e")/3)-INT(COUNTIF(AG30:BA30,"t")/3),"") -> 17 | BC30: =IFERROR(BB30/$BC$4,"") -> 1 | BD30: =IFERROR(COUNTIF(AG30:BA30,"A"),"") -> 0 | BE30: =IFERROR((BD30/$BC$4),"") -> 0 | BF30: =IFERROR(COUNTIF(AG30:BA30,"E"),"") -> 0 | BG30: =IFERROR((BF30/$BC$4),"") -> 0 | BP30: 24
... A37: ='3A 2025 - 2026 DATOS DEL ESTUDI'!N34 -> 22023376 | B37: 31 | C37: ='3A 2025 - 2026 DATOS DEL ESTUDI'!B34 -> Rossier Analiz Pérez Rodríguez | D37: P | E37: P | F37: P | G37: P | H37: P | Y37: =IFERROR(COUNTIF(D37:X37,"P")+COUNTIF(D37:X37,"e")+COUNTIF(D37:X37,"t")-INT(COUNTIF(D37:X37,"e")/3)-INT(COUNTIF(D37:X37,"t")/3),"") -> 5 | Z37: =IFERROR((Y37/$Z$4),"") -> 1 | AA37: =IFERROR(COUNTIF(D37:X37,"A"),"") -> 0 | AB37: =IFERROR((AA37/$Z$4),"") -> 0 | AC37: =IFERROR(COUNTIF(D37:X37,"E"),"") -> 0 | AD37: =IFERROR((AC37/$Z$4),"") -> 0 | AE37: 31 | AF37: =C37 -> Rossier Analiz Pérez Rodríguez | AG37: P | AH37: P | AI37: P | AJ37: P | AK37: P | AL37: P | AM37: P | AN37: P | AO37: P | AP37: P | AQ37: P | AR37: P | AU37: P | AV37: P | AW37: P | AY37: P | BA37: P | BB37: =IFERROR(COUNTIF(AG37:BA37,"P")+COUNTIF(AG37:BA37,"e")+COUNTIF(AG37:BA37,"t")-INT(COUNTIF(AG37:BA37,"e")/3)-INT(COUNTIF(AG37:BA37,"t")/3),"") -> 17 | BC37: =IFERROR(BB37/$BC$4,"") -> 1 | BD37: =IFERROR(COUNTIF(AG37:BA37,"A"),"") -> 0 | BE37: =IFERROR((BD37/$BC$4),"") -> 0 | BF37: =IFERROR(COUNTIF(AG37:BA37,"E"),"") -> 0 | BG37: =IFERROR((BF37/$BC$4),"") -> 0 | BP37: 31
A38: ='3A 2025 - 2026 DATOS DEL ESTUDI'!N35 -> 6925657 | B38: 32 | C38: ='3A 2025 - 2026 DATOS DEL ESTUDI'!B35 -> Joseph Francisco Ramírez Espinosa | D38: P | E38: P | F38: P | G38: P | H38: P | Y38: =IFERROR(COUNTIF(D38:X38,"P")+COUNTIF(D38:X38,"e")+COUNTIF(D38:X38,"t")-INT(COUNTIF(D38:X38,"e")/3)-INT(COUNTIF(D38:X38,"t")/3),"") -> 5 | Z38: =IFERROR((Y38/$Z$4),"") -> 1 | AA38: =IFERROR(COUNTIF(D38:X38,"A"),"") -> 0 | AB38: =IFERROR((AA38/$Z$4),"") -> 0 | AC38: =IFERROR(COUNTIF(D38:X38,"E"),"") -> 0 | AD38: =IFERROR((AC38/$Z$4),"") -> 0 | AE38: 32 | AF38: =C38 -> Joseph Francisco Ramírez Espinosa | AG38: P | AH38: P | AI38: P | AJ38: P | AK38: P | AL38: P | AM38: P | AN38: P | AO38: P | AP38: P | AQ38: P | AR38: P | AU38: P | AV38: P | AW38: P | AY38: P | BA38: P | BB38: =IFERROR(COUNTIF(AG38:BA38,"P")+COUNTIF(AG38:BA38,"e")+COUNTIF(AG38:BA38,"t")-INT(COUNTIF(AG38:BA38,"e")/3)-INT(COUNTIF(AG38:BA38,"t")/3),"") -> 17 | BC38: =IFERROR(BB38/$BC$4,"") -> 1 | BD38: =IFERROR(COUNTIF(AG38:BA38,"A"),"") -> 0 | BE38: =IFERROR((BD38/$BC$4),"") -> 0 | BF38: =IFERROR(COUNTIF(AG38:BA38,"E"),"") -> 0 | BG38: =IFERROR((BF38/$BC$4),"") -> 0
A39: ='3A 2025 - 2026 DATOS DEL ESTUDI'!N36 -> 12009792 | B39: 33 | C39: ='3A 2025 - 2026 DATOS DEL ESTUDI'!B36 -> Yariel Alfonso Ramos | D39: P | E39: P | F39: P | G39: P | H39: P | Y39: =IFERROR(COUNTIF(D39:X39,"P")+COUNTIF(D39:X39,"e")+COUNTIF(D39:X39,"t")-INT(COUNTIF(D39:X39,"e")/3)-INT(COUNTIF(D39:X39,"t")/3),"") -> 5 | Z39: =IFERROR((Y39/$Z$4),"") -> 1 | AA39: =IFERROR(COUNTIF(D39:X39,"A"),"") -> 0 | AB39: =IFERROR((AA39/$Z$4),"") -> 0 | AC39: =IFERROR(COUNTIF(D39:X39,"E"),"") -> 0 | AD39: =IFERROR((AC39/$Z$4),"") -> 0 | AE39: 33 | AF39: =C39 -> Yariel Alfonso Ramos | AG39: P | AH39: P | AI39: P | AJ39: P | AK39: P | AL39: P | AM39: P | AN39: P | AO39: P | AP39: P | AQ39: P | AR39: P | AU39: P | AV39: P | AW39: P | AY39: P | BA39: P | BB39: =IFERROR(COUNTIF(AG39:BA39,"P")+COUNTIF(AG39:BA39,"e")+COUNTIF(AG39:BA39,"t")-INT(COUNTIF(AG39:BA39,"e")/3)-INT(COUNTIF(AG39:BA39,"t")/3),"") -> 17 | BC39: =IFERROR(BB39/$BC$4,"") -> 1 | BD39: =IFERROR(COUNTIF(AG39:BA39,"A"),"") -> 0 | BE39: =IFERROR((BD39/$BC$4),"") -> 0 | BF39: =IFERROR(COUNTIF(AG39:BA39,"E"),"") -> 0 | BG39: =IFERROR((BF39/$BC$4),"") -> 0
A40: ='3A 2025 - 2026 DATOS DEL ESTUDI'!N37 -> 32790184 | B40: 34 | C40: ='3A 2025 - 2026 DATOS DEL ESTUDI'!B37 -> Carlos David Rodríguez Almánzar | D40: P | E40: P | F40: P | G40: P | H40: P | Y40: =IFERROR(COUNTIF(D40:X40,"P")+COUNTIF(D40:X40,"e")+COUNTIF(D40:X40,"t")-INT(COUNTIF(D40:X40,"e")/3)-INT(COUNTIF(D40:X40,"t")/3),"") -> 5 | Z40: =IFERROR((Y40/$Z$4),"") -> 1 | AA40: =IFERROR(COUNTIF(D40:X40,"A"),"") -> 0 | AB40: =IFERROR((AA40/$Z$4),"") -> 0 | AC40: =IFERROR(COUNTIF(D40:X40,"E"),"") -> 0 | AD40: =IFERROR((AC40/$Z$4),"") -> 0 | AE40: 34 | AF40: =C40 -> Carlos David Rodríguez Almánzar | AG40: P | AH40: P | AI40: P | AJ40: P | AK40: P | AL40: P | AM40: P | AN40: P | AO40: P | AP40: P | AQ40: P | AR40: P | AU40: P | AV40: P | AW40: P | AY40: P | BA40: P | BB40: =IFERROR(COUNTIF(AG40:BA40,"P")+COUNTIF(AG40:BA40,"e")+COUNTIF(AG40:BA40,"t")-INT(COUNTIF(AG40:BA40,"e")/3)-INT(COUNTIF(AG40:BA40,"t")/3),"") -> 17 | BC40: =IFERROR(BB40/$BC$4,"") -> 1 | BD40: =IFERROR(COUNTIF(AG40:BA40,"A"),"") -> 0 | BE40: =IFERROR((BD40/$BC$4),"") -> 0 | BF40: =IFERROR(COUNTIF(AG40:BA40,"E"),"") -> 0 | BG40: =IFERROR((BF40/$BC$4),"") -> 0
A41: ='3A 2025 - 2026 DATOS DEL ESTUDI'!N38 -> 32790393 | B41: 35 | C41: ='3A 2025 - 2026 DATOS DEL ESTUDI'!B38 -> Darianni Santos Medina | D41: P | E41: P | F41: P | G41: P | H41: P | Y41: =IFERROR(COUNTIF(D41:X41,"P")+COUNTIF(D41:X41,"e")+COUNTIF(D41:X41,"t")-INT(COUNTIF(D41:X41,"e")/3)-INT(COUNTIF(D41:X41,"t")/3),"") -> 5 | Z41: =IFERROR((Y41/$Z$4),"") -> 1 | AA41: =IFERROR(COUNTIF(D41:X41,"A"),"") -> 0 | AB41: =IFERROR((AA41/$Z$4),"") -> 0 | AC41: =IFERROR(COUNTIF(D41:X41,"E"),"") -> 0 | AD41: =IFERROR((AC41/$Z$4),"") -> 0 | AE41: 35 | AF41: =C41 -> Darianni Santos Medina | AG41: P | AH41: P | AI41: P | AJ41: P | AK41: P | AL41: P | AM41: P | AN41: P | AO41: P | AP41: P | AQ41: P | AR41: P | AU41: P | AV41: P | AW41: P | AY41: P | BA41: P | BB41: =IFERROR(COUNTIF(AG41:BA41,"P")+COUNTIF(AG41:BA41,"e")+COUNTIF(AG41:BA41,"t")-INT(COUNTIF(AG41:BA41,"e")/3)-INT(COUNTIF(AG41:BA41,"t")/3),"") -> 17 | BC41: =IFERROR(BB41/$BC$4,"") -> 1 | BD41: =IFERROR(COUNTIF(AG41:BA41,"A"),"") -> 0 | BE41: =IFERROR((BD41/$BC$4),"") -> 0 | BF41: =IFERROR(COUNTIF(AG41:BA41,"E"),"") -> 0 | BG41: =IFERROR((BF41/$BC$4),"") -> 0
A42: ='3A 2025 - 2026 DATOS DEL ESTUDI'!N39 -> 6947490 | B42: 36 | C42: ='3A 2025 - 2026 DATOS DEL ESTUDI'!B39 -> Rosyeli Carolina Tavarez Reyes | D42: P | E42: P | F42: P | G42: P | H42: P | Y42: =IFERROR(COUNTIF(D42:X42,"P")+COUNTIF(D42:X42,"e")+COUNTIF(D42:X42,"t")-INT(COUNTIF(D42:X42,"e")/3)-INT(COUNTIF(D42:X42,"t")/3),"") -> 5 | Z42: =IFERROR((Y42/$Z$4),"") -> 1 | AA42: =IFERROR(COUNTIF(D42:X42,"A"),"") -> 0 | AB42: =IFERROR((AA42/$Z$4),"") -> 0 | AC42: =IFERROR(COUNTIF(D42:X42,"E"),"") -> 0 | AD42: =IFERROR((AC42/$Z$4),"") -> 0 | AE42: 36 | AF42: =C42 -> Rosyeli Carolina Tavarez Reyes | AG42: P | AH42: P | AI42: P | AJ42: P | AK42: P | AL42: P | AM42: P | AN42: P | AO42: P | AP42: P | AQ42: P | AR42: P | AU42: P | AV42: P | AW42: P | AY42: P | BA42: P | BB42: =IFERROR(COUNTIF(AG42:BA42,"P")+COUNTIF(AG42:BA42,"e")+COUNTIF(AG42:BA42,"t")-INT(COUNTIF(AG42:BA42,"e")/3)-INT(COUNTIF(AG42:BA42,"t")/3),"") -> 17 | BC42: =IFERROR(BB42/$BC$4,"") -> 1 | BD42: =IFERROR(COUNTIF(AG42:BA42,"A"),"") -> 0 | BE42: =IFERROR((BD42/$BC$4),"") -> 0 | BF42: =IFERROR(COUNTIF(AG42:BA42,"E"),"") -> 0 | BG42: =IFERROR((BF42/$BC$4),"") -> 0
A43: ='3A 2025 - 2026 DATOS DEL ESTUDI'!N40 -> 32590071 | B43: 37 | C43: ='3A 2025 - 2026 DATOS DEL ESTUDI'!B40 -> Melani Taveras Bautista | D43: P | E43: P | F43: P | G43: P | H43: P | Y43: =IFERROR(COUNTIF(D43:X43,"P")+COUNTIF(D43:X43,"e")+COUNTIF(D43:X43,"t")-INT(COUNTIF(D43:X43,"e")/3)-INT(COUNTIF(D43:X43,"t")/3),"") -> 5 | Z43: =IFERROR((Y43/$Z$4),"") -> 1 | AA43: =IFERROR(COUNTIF(D43:X43,"A"),"") -> 0 | AB43: =IFERROR((AA43/$Z$4),"") -> 0 | AC43: =IFERROR(COUNTIF(D43:X43,"E"),"") -> 0 | AD43: =IFERROR((AC43/$Z$4),"") -> 0 | AE43: 37 | AF43: =C43 -> Melani Taveras Bautista | AG43: P | AH43: P | AI43: P | AJ43: P | AK43: P | AL43: P | AM43: P | AN43: P | AO43: P | AP43: P | AQ43: P | AR43: P | AU43: P | AV43: P | AW43: P | AY43: P | BA43: P | BB43: =IFERROR(COUNTIF(AG43:BA43,"P")+COUNTIF(AG43:BA43,"e")+COUNTIF(AG43:BA43,"t")-INT(COUNTIF(AG43:BA43,"e")/3)-INT(COUNTIF(AG43:BA43,"t")/3),"") -> 17 | BC43: =IFERROR(BB43/$BC$4,"") -> 1 | BD43: =IFERROR(COUNTIF(AG43:BA43,"A"),"") -> 0 | BE43: =IFERROR((BD43/$BC$4),"") -> 0 | BF43: =IFERROR(COUNTIF(AG43:BA43,"E"),"") -> 0 | BG43: =IFERROR((BF43/$BC$4),"") -> 0
A44: ='3A 2025 - 2026 DATOS DEL ESTUDI'!N41 -> 32790609 | B44: 38 | C44: ='3A 2025 - 2026 DATOS DEL ESTUDI'!B41 -> Arianny Tejada Guzmán | D44: P | E44: P | F44: P | G44: P | H44: P | Y44: =IFERROR(COUNTIF(D44:X44,"P")+COUNTIF(D44:X44,"e")+COUNTIF(D44:X44,"t")-INT(COUNTIF(D44:X44,"e")/3)-INT(COUNTIF(D44:X44,"t")/3),"") -> 5 | Z44: =IFERROR((Y44/$Z$4),"") -> 1 | AA44: =IFERROR(COUNTIF(D44:X44,"A"),"") -> 0 | AB44: =IFERROR((AA44/$Z$4),"") -> 0 | AC44: =IFERROR(COUNTIF(D44:X44,"E"),"") -> 0 | AD44: =IFERROR((AC44/$Z$4),"") -> 0 | AE44: 38 | AF44: =C44 -> Arianny Tejada Guzmán | AG44: P | AH44: P | AI44: P | AJ44: P | AK44: P | AL44: P | AM44: P | AN44: P | AO44: P | AP44: P | AQ44: P | AR44: P | AU44: P | AV44: P | AW44: P | AY44: P | BA44: P | BB44: =IFERROR(COUNTIF(AG44:BA44,"P")+COUNTIF(AG44:BA44,"e")+COUNTIF(AG44:BA44,"t")-INT(COUNTIF(AG44:BA44,"e")/3)-INT(COUNTIF(AG44:BA44,"t")/3),"") -> 17 | BC44: =IFERROR(BB44/$BC$4,"") -> 1 | BD44: =IFERROR(COUNTIF(AG44:BA44,"A"),"") -> 0 | BE44: =IFERROR((BD44/$BC$4),"") -> 0 | BF44: =IFERROR(COUNTIF(AG44:BA44,"E"),"") -> 0 | BG44: =IFERROR((BF44/$BC$4),"") -> 0
A45: ='3A 2025 - 2026 DATOS DEL ESTUDI'!N42 -> 6758894 | B45: 39 | C45: ='3A 2025 - 2026 DATOS DEL ESTUDI'!B42 -> Jeilyn Aliah Tejada | D45: P | E45: P | F45: P | G45: P | H45: P | Y45: =IFERROR(COUNTIF(D45:X45,"P")+COUNTIF(D45:X45,"e")+COUNTIF(D45:X45,"t")-INT(COUNTIF(D45:X45,"e")/3)-INT(COUNTIF(D45:X45,"t")/3),"") -> 5 | Z45: =IFERROR((Y45/$Z$4),"") -> 1 | AA45: =IFERROR(COUNTIF(D45:X45,"A"),"") -> 0 | AB45: =IFERROR((AA45/$Z$4),"") -> 0 | AC45: =IFERROR(COUNTIF(D45:X45,"E"),"") -> 0 | AD45: =IFERROR((AC45/$Z$4),"") -> 0 | AE45: 39 | AF45: =C45 -> Jeilyn Aliah Tejada | AG45: P | AH45: P | AI45: P | AJ45: P | AK45: P | AL45: P | AM45: P | AN45: P | AO45: P | AP45: P | AQ45: P | AR45: P | AU45: P | AV45: P | AW45: P | AY45: P | BA45: P | BB45: =IFERROR(COUNTIF(AG45:BA45,"P")+COUNTIF(AG45:BA45,"e")+COUNTIF(AG45:BA45,"t")-INT(COUNTIF(AG45:BA45,"e")/3)-INT(COUNTIF(AG45:BA45,"t")/3),"") -> 17 | BC45: =IFERROR(BB45/$BC$4,"") -> 1 | BD45: =IFERROR(COUNTIF(AG45:BA45,"A"),"") -> 0 | BE45: =IFERROR((BD45/$BC$4),"") -> 0 | BF45: =IFERROR(COUNTIF(AG45:BA45,"E"),"") -> 0 | BG45: =IFERROR((BF45/$BC$4),"") -> 0
